<?xml version="1.0"?>
<robot xmlns:xacro="http://www.ros.org/wiki/xacro" name="roboco">

  <material name="silver"> <color rgba="0.7 0.7 0.7 1"/> </material>
  <material name="black"> <color rgba="0.1 0.1 0.1 1"/> </material>
  <material name="red"> <color rgba="0.8 0.1 0.1 1"/> </material>

  <link name="base_footprint"/>

  <joint name="base_joint" type="fixed">
    <parent link="base_footprint"/>
    <child link="base_link"/>
    <origin xyz="0 0 0.04" rpy="0 0 0"/>
  </joint>

  <link name="base_link">
    <visual>
      <geometry> <box size="0.225 0.16 0.03"/> </geometry>
      <material name="silver"/>
    </visual>
    <collision>
      <geometry> <box size="0.225 0.16 0.03"/> </geometry>
    </collision>
    <inertial>
      <mass value="3.0"/>
      <inertia ixx="0.006" ixy="0" ixz="0" iyy="0.012" iyz="0" izz="0.018"/>
    </inertial>
  </link>

  <xacro:macro name="omni_wheel" params="prefix x_reflect y_reflect">
    <link name="${prefix}_wheel">
      <visual>
        <geometry> <cylinder radius="0.03" length="0.025"/> </geometry>
        <material name="black"/>
      </visual>
      <collision>
        <geometry> <cylinder radius="0.03" length="0.025"/> </geometry>
      </collision>
      <inertial>
        <mass value="0.2"/>
        <inertia ixx="0.00005" ixy="0" ixz="0" iyy="0.00005" iyz="0" izz="0.00009"/>
      </inertial>
    </link>

    <joint name="${prefix}_wheel_joint" type="continuous">
      <parent link="base_link"/>
      <child link="${prefix}_wheel"/>
      <origin xyz="${x_reflect * 0.08} ${y_reflect * 0.11} -0.01" rpy="-1.5708 0 0"/>
      <axis xyz="0 0 1"/>
    </joint>
  </xacro:macro>

  <xacro:omni_wheel prefix="front_left" x_reflect="1" y_reflect="1" />
  <xacro:omni_wheel prefix="front_right" x_reflect="1" y_reflect="-1" />
  <xacro:omni_wheel prefix="rear_left" x_reflect="-1" y_reflect="1" />
  <xacro:omni_wheel prefix="rear_right" x_reflect="-1" y_reflect="-1" />

  <link name="laser_frame">
    <visual>
      <geometry> <cylinder radius="0.03" length="0.04"/> </geometry>
      <material name="red"/>
    </visual>
    <collision>
      <geometry> <cylinder radius="0.03" length="0.04"/> </geometry>
    </collision>
    <inertial>
      <mass value="0.1"/>
      <inertia ixx="0.0001" ixy="0" ixz="0" iyy="0.0001" iyz="0" izz="0.0001"/>
    </inertial>
  </link>

  <joint name="laser_joint" type="fixed">
    <parent link="base_link"/>
    <child link="laser_frame"/>
    <origin xyz="0.05 0 0.035" rpy="0 0 0"/>
  </joint>

  <link name="imu_link">
    <visual>
      <geometry> <box size="0.02 0.02 0.01"/> </geometry>
      <material name="black"/>
    </visual>
    <inertial>
      <mass value="0.01"/>
      <inertia ixx="0.00001" ixy="0" ixz="0" iyy="0.00001" iyz="0" izz="0.00001"/>
    </inertial>
  </link>

  <joint name="imu_joint" type="fixed">
    <parent link="base_link"/>
    <child link="imu_link"/>
    <origin xyz="0 0 0.015" rpy="0 0 0"/>
  </joint>

  <gazebo>
    <plugin filename="gz-sim-mecanum-drive-system" name="gz::sim::systems::MecanumDrive">
      <front_left_joint>front_left_wheel_joint</front_left_joint>
      <front_right_joint>front_right_wheel_joint</front_right_joint>
      <back_left_joint>rear_left_wheel_joint</back_left_joint>
      <back_right_joint>rear_right_wheel_joint</back_right_joint>
      <wheel_separation>0.22</wheel_separation>
      <wheelbase>0.16</wheelbase>
      <wheel_radius>0.03</wheel_radius>
      <topic>/cmd_vel</topic>
      <odom_topic>/odom</odom_topic>
      <tf_topic>/tf</tf_topic>
      <frame_id>odom</frame_id>
      <child_frame_id>base_footprint</child_frame_id>
    </plugin>

    <plugin filename="gz-sim-joint-state-publisher-system" name="gz::sim::systems::JointStatePublisher">
      <topic>/joint_states</topic>
    </plugin>

    <plugin filename="gz-sim-sensors-system" name="gz::sim::systems::Sensors">
      <render_engine>ogre2</render_engine>
    </plugin>
  </gazebo>

  <gazebo reference="laser_frame">
    <sensor name="lidar" type="gpu_lidar">
      <pose>0 0 0 0 0 0</pose>
      <visualize>true</visualize>
      <always_on>true</always_on>
      <update_rate>10</update_rate>
      <lidar>
        <scan>
          <horizontal>
            <samples>360</samples>
            <resolution>1</resolution>
            <min_angle>-3.14159</min_angle>
            <max_angle>3.14159</max_angle>
          </horizontal>
        </scan>
        <range>
          <min>0.15</min>
          <max>12.0</max>
        </range>
      </lidar>
      <topic>/scan</topic>
      <gz_frame_id>laser_frame</gz_frame_id>
    </sensor>
  </gazebo>

  <gazebo reference="imu_link">
    <sensor name="imu_sensor" type="imu">
      <always_on>true</always_on>
      <update_rate>100</update_rate>
      <topic>/imu</topic>
      <gz_frame_id>imu_link</gz_frame_id>
    </sensor>
  </gazebo>

</robot>